<?xml version="1.0"?>
<robot name="simple_diff_drive_generated" xmlns:xacro="http://ros.org/wiki/xacro">

    <link name="base_link">
        <visual>
            <geometry>
                <box size="0.3 0.2 0.05"/>
            </geometry>
            <material name="yellow">
                <color rgba="1.0 1.0 0.0 1.0"/>
            </material>
        </visual>
    </link>
    
    <joint name="left_wheel_joint" type="continuous">
        <parent link="base_link"/>
        <child link="left_wheel_link"/>
        <origin xyz="-0.09 0.15 0" rpy="-1.5708 0 0"/>
        <axis xyz="0 0 1"/>
    </joint>

    <link name="left_wheel_link">
        <visual>
            <geometry>
                <cylinder radius="0.05" length="0.04"/>
            </geometry>
            <material name="blue">
                <color rgba="0.0 0.0 1.0 1.0"/>
            </material>
        </visual>
    </link>
    
    <joint name="right_wheel_joint" type="continuous">
        <parent link="base_link"/>
        <child link="right_wheel_link"/>
        <origin xyz="-0.09 -0.15 0" rpy="1.5708 0 0"/>
        <axis xyz="0 0 -1"/>
    </joint>

    <link name="right_wheel_link">
        <visual>
            <geometry>
                <cylinder radius="0.05" length="0.04"/>
            </geometry>
            <material name="red">
                <color rgba="1.0 0.0 0.0 1.0"/>
            </material>
        </visual>
    </link>
    
    <joint name="caster_joint" type="fixed">
        <parent link="base_link"/>
        <child link="caster_link"/>
        <origin xyz="0.09 0 -0.04" rpy="0 0 0"/>
    </joint>

    <link name="caster_link">
        <visual>
            <geometry>
                <sphere radius="0.03"/>
            </geometry>
            <material name="gray">
                <color rgba="0.6 0.6 0.6 1.0"/>
            </material>
        </visual>
    </link>
    </robot>
